<!DOCTYPE html>
<html lang="en">
  <head>
    <meta charset="UTF-8" />
    <meta name="viewport" content="width=device-width, initial-scale=1.0" />
    <title>Document</title>
  </head>
  <body>
    <script>
      const promise = new Promise((resolve, reject) => {
        reject("aaaa");
      });

      // promise
      //   .catch((err) => {
      //     console.log("失败", err);
      //     // 这里的catch方法返回的是一个Promise对象，所以会继续执行后续的then方法
      //     return "失败2";
      //   })
      //   .then((res) => {
      //     console.log("成功", res);
      //     return "成功2";
      //   })
      //   .then((res) => {
      //     console.log("成功2", res);
      //     return new Promise((resolve, reject) => {
      //       resolve("成功3");
      //     });
      //   })
      //   .catch((err) => {
      //     console.log("失败", err);
      //   });
      promise
        .then((res) => {
          console.log("成功", res);
          // 如果在then方法中抛出异常，那么会直接执行最近的catch方法
          throw new Error("then方法中抛出异常");
        })
        .then((res) => {
          console.log("成功2", res);
        })
        .then((res) => {
          console.log("成功3", res);
        })
        // 如果promise对象的状态是rejected，那么会直接执行最近的catch方法
        .catch((err) => {
          console.log("失败", err);
        });
    </script>
  </body>
</html>
